<?xml version="1.0" ?>
<robot name="two_wheel_drive" xmlns:xacro="http://www.ros.org/wiki/xacro">

<xacro:include filename="$(find two_wheel_drive_description)/urdf/materials.xacro" />
<xacro:include filename="$(find two_wheel_drive_description)/urdf/two_wheel_drive.trans" />
<xacro:include filename="$(find two_wheel_drive_description)/urdf/two_wheel_drive.gazebo" />
<link name="base_link">
  <inertial>
    <origin xyz="0.0032536371479730836 1.7087196595133478e-17 0.05193914806588865" rpy="0 0 0"/>
    <mass value="16.713176720752102"/>
    <inertia ixx="0.057482" iyy="0.061252" izz="0.108997" ixy="0.0" iyz="0.0" ixz="-0.00207"/>
  </inertial>
  <visual>
    <origin xyz="0 0 0" rpy="0 0 0"/>
    <geometry>
      <mesh filename="file://$(find two_wheel_drive_description)/meshes/base_link.stl" scale="0.001 0.001 0.001"/>
    </geometry>
    <material name="silver"/>
  </visual>
  <collision>
    <origin xyz="0 0 0" rpy="0 0 0"/>
    <geometry>
      <mesh filename="file://$(find two_wheel_drive_description)/meshes/base_link.stl" scale="0.001 0.001 0.001"/>
    </geometry>
  </collision>
</link>

<link name="lidar_1">
  <inertial>
    <origin xyz="0.0 0.0 0.010000000000000009" rpy="0 0 0"/>
    <mass value="0.6042068071016571"/>
    <inertia ixx="0.000205" iyy="0.000205" izz="0.00037" ixy="-0.0" iyz="-0.0" ixz="0.0"/>
  </inertial>
  <visual>
    <origin xyz="-0.06 -0.0 -0.105" rpy="0 0 0"/>
    <geometry>
      <mesh filename="file://$(find two_wheel_drive_description)/meshes/lidar_1.stl" scale="0.001 0.001 0.001"/>
    </geometry>
    <material name="silver"/>
  </visual>
  <collision>
    <origin xyz="-0.06 -0.0 -0.105" rpy="0 0 0"/>
    <geometry>
      <mesh filename="file://$(find two_wheel_drive_description)/meshes/lidar_1.stl" scale="0.001 0.001 0.001"/>
    </geometry>
  </collision>
</link>

<link name="right_wheel_1">
  <inertial>
    <origin xyz="9.650038500203382e-18 -0.015000000000000013 6.938893903907228e-18" rpy="0 0 0"/>
    <mass value="1.8496126748009902"/>
    <inertia ixx="0.001295" iyy="0.002312" izz="0.001295" ixy="-0.0" iyz="0.0" ixz="0.0"/>
  </inertial>
  <visual>
    <origin xyz="-0.0 0.1 -0.05" rpy="0 0 0"/>
    <geometry>
      <mesh filename="file://$(find two_wheel_drive_description)/meshes/right_wheel_1.stl" scale="0.001 0.001 0.001"/>
    </geometry>
    <material name="silver"/>
  </visual>
  <collision>
    <origin xyz="-0.0 0.1 -0.05" rpy="0 0 0"/>
    <geometry>
      <mesh filename="file://$(find two_wheel_drive_description)/meshes/right_wheel_1.stl" scale="0.001 0.001 0.001"/>
    </geometry>
  </collision>
</link>

<link name="left_wheel_1">
  <inertial>
    <origin xyz="9.650038500203382e-18 0.014999999999999972 6.938893903907228e-18" rpy="0 0 0"/>
    <mass value="1.8496126748009902"/>
    <inertia ixx="0.001295" iyy="0.002312" izz="0.001295" ixy="0.0" iyz="-0.0" ixz="0.0"/>
  </inertial>
  <visual>
    <origin xyz="-0.0 -0.1 -0.05" rpy="0 0 0"/>
    <geometry>
      <mesh filename="file://$(find two_wheel_drive_description)/meshes/left_wheel_1.stl" scale="0.001 0.001 0.001"/>
    </geometry>
    <material name="silver"/>
  </visual>
  <collision>
    <origin xyz="-0.0 -0.1 -0.05" rpy="0 0 0"/>
    <geometry>
      <mesh filename="file://$(find two_wheel_drive_description)/meshes/left_wheel_1.stl" scale="0.001 0.001 0.001"/>
    </geometry>
  </collision>
</link>

<joint name="Rigid 1" type="fixed">
  <origin xyz="0.06 0.0 0.105" rpy="0 0 0"/>
  <parent link="base_link"/>
  <child link="lidar_1"/>
</joint>

<joint name="Revolute 2" type="continuous">
  <origin xyz="0.0 -0.1 0.05" rpy="0 0 0"/>
  <parent link="base_link"/>
  <child link="right_wheel_1"/>
  <axis xyz="0.0 -1.0 0.0"/>
</joint>

<joint name="Revolute 3" type="continuous">
  <origin xyz="0.0 0.1 0.05" rpy="0 0 0"/>
  <parent link="base_link"/>
  <child link="left_wheel_1"/>
  <axis xyz="0.0 1.0 0.0"/>
</joint>

</robot>
